[2022-06-17 19:02:27,880] {taskinstance.py:1159} INFO - Dependencies all met for <TaskInstance: e-t-l.test manual__2022-06-17T19:02:16.138992+00:00 [queued]>
[2022-06-17 19:02:28,023] {taskinstance.py:1159} INFO - Dependencies all met for <TaskInstance: e-t-l.test manual__2022-06-17T19:02:16.138992+00:00 [queued]>
[2022-06-17 19:02:28,038] {taskinstance.py:1356} INFO - 
--------------------------------------------------------------------------------
[2022-06-17 19:02:28,054] {taskinstance.py:1357} INFO - Starting attempt 1 of 1
[2022-06-17 19:02:28,102] {taskinstance.py:1358} INFO - 
--------------------------------------------------------------------------------
[2022-06-17 19:02:28,456] {taskinstance.py:1377} INFO - Executing <Task(PythonOperator): test> on 2022-06-17 19:02:16.138992+00:00
[2022-06-17 19:02:28,487] {standard_task_runner.py:52} INFO - Started process 18557 to run task
[2022-06-17 19:02:28,518] {standard_task_runner.py:79} INFO - Running: ['***', 'tasks', 'run', 'e-t-l', 'test', 'manual__2022-06-17T19:02:16.138992+00:00', '--job-id', '554', '--raw', '--subdir', 'DAGS_FOLDER/new-new.py', '--cfg-path', '/tmp/tmpjj6g88t1', '--error-file', '/tmp/tmpkxtvko03']
[2022-06-17 19:02:28,533] {standard_task_runner.py:80} INFO - Job 554: Subtask test
[2022-06-17 19:02:29,432] {task_command.py:370} INFO - Running <TaskInstance: e-t-l.test manual__2022-06-17T19:02:16.138992+00:00 [running]> on host fe209149cfc1
[2022-06-17 19:02:30,860] {taskinstance.py:1571} INFO - Exporting the following env vars:
AIRFLOW_CTX_DAG_OWNER=***
AIRFLOW_CTX_DAG_ID=e-t-l
AIRFLOW_CTX_TASK_ID=test
AIRFLOW_CTX_EXECUTION_DATE=2022-06-17T19:02:16.138992+00:00
AIRFLOW_CTX_TRY_NUMBER=1
AIRFLOW_CTX_DAG_RUN_ID=manual__2022-06-17T19:02:16.138992+00:00
[2022-06-17 19:02:31,117] {base.py:68} INFO - Using connection ID 'mysql_con' for task execution.
[2022-06-17 19:02:31,361] {base.py:68} INFO - Using connection ID 'mysql_con' for task execution.
[2022-06-17 19:02:31,475] {taskinstance.py:1889} ERROR - Task failed with exception
Traceback (most recent call last):
  File "/home/airflow/.local/lib/python3.7/site-packages/airflow/operators/python.py", line 171, in execute
    return_value = self.execute_callable()
  File "/home/airflow/.local/lib/python3.7/site-packages/airflow/operators/python.py", line 189, in execute_callable
    return self.python_callable(*self.op_args, **self.op_kwargs)
  File "/opt/airflow/dags/new-new.py", line 25, in get_source_data
    source_db_store_result=source_db_store_result.to_dict()
AttributeError: 'tuple' object has no attribute 'to_dict'
[2022-06-17 19:02:31,585] {taskinstance.py:1400} INFO - Marking task as FAILED. dag_id=e-t-l, task_id=test, execution_date=20220617T190216, start_date=20220617T190227, end_date=20220617T190231
[2022-06-17 19:02:32,034] {standard_task_runner.py:97} ERROR - Failed to execute job 554 for task test ('tuple' object has no attribute 'to_dict'; 18557)
[2022-06-17 19:02:32,104] {local_task_job.py:156} INFO - Task exited with return code 1
[2022-06-17 19:02:32,555] {local_task_job.py:273} INFO - 0 downstream tasks scheduled from follow-on schedule check
