[2022-06-17 10:30:26,090] {taskinstance.py:1159} INFO - Dependencies all met for <TaskInstance: etl-processing.test manual__2022-06-17T10:30:20.880329+00:00 [queued]>
[2022-06-17 10:30:26,151] {taskinstance.py:1159} INFO - Dependencies all met for <TaskInstance: etl-processing.test manual__2022-06-17T10:30:20.880329+00:00 [queued]>
[2022-06-17 10:30:26,152] {taskinstance.py:1356} INFO - 
--------------------------------------------------------------------------------
[2022-06-17 10:30:26,152] {taskinstance.py:1357} INFO - Starting attempt 1 of 1
[2022-06-17 10:30:26,153] {taskinstance.py:1358} INFO - 
--------------------------------------------------------------------------------
[2022-06-17 10:30:26,222] {taskinstance.py:1377} INFO - Executing <Task(PythonOperator): test> on 2022-06-17 10:30:20.880329+00:00
[2022-06-17 10:30:26,239] {standard_task_runner.py:52} INFO - Started process 651 to run task
[2022-06-17 10:30:26,245] {standard_task_runner.py:79} INFO - Running: ['***', 'tasks', 'run', 'etl-processing', 'test', 'manual__2022-06-17T10:30:20.880329+00:00', '--job-id', '532', '--raw', '--subdir', 'DAGS_FOLDER/testing_etl.py', '--cfg-path', '/tmp/tmpn3fsyiae', '--error-file', '/tmp/tmp_19ry9vg']
[2022-06-17 10:30:26,252] {standard_task_runner.py:80} INFO - Job 532: Subtask test
[2022-06-17 10:30:26,475] {task_command.py:370} INFO - Running <TaskInstance: etl-processing.test manual__2022-06-17T10:30:20.880329+00:00 [running]> on host fe209149cfc1
[2022-06-17 10:30:26,984] {taskinstance.py:1571} INFO - Exporting the following env vars:
AIRFLOW_CTX_DAG_OWNER=***
AIRFLOW_CTX_DAG_ID=etl-processing
AIRFLOW_CTX_TASK_ID=test
AIRFLOW_CTX_EXECUTION_DATE=2022-06-17T10:30:20.880329+00:00
AIRFLOW_CTX_TRY_NUMBER=1
AIRFLOW_CTX_DAG_RUN_ID=manual__2022-06-17T10:30:20.880329+00:00
[2022-06-17 10:30:27,074] {base.py:68} INFO - Using connection ID 'mysql_con' for task execution.
[2022-06-17 10:30:27,267] {base.py:68} INFO - Using connection ID 'postgres_conn' for task execution.
[2022-06-17 10:30:27,600] {taskinstance.py:1889} ERROR - Task failed with exception
Traceback (most recent call last):
  File "/home/airflow/.local/lib/python3.7/site-packages/airflow/operators/python.py", line 171, in execute
    return_value = self.execute_callable()
  File "/home/airflow/.local/lib/python3.7/site-packages/airflow/operators/python.py", line 189, in execute_callable
    return self.python_callable(*self.op_args, **self.op_kwargs)
  File "/opt/airflow/dags/testing_etl.py", line 48, in get_source_data
    cursor.execute(sql, tuple(i))
psycopg2.errors.InvalidDatetimeFormat: invalid input syntax for type timestamp: "NaT"
LINE 1: ... VALUES (2345692,NULL,'NaN'::float,0,'NaN'::float,'NaT'::tim...
                                                             ^

[2022-06-17 10:30:27,680] {taskinstance.py:1400} INFO - Marking task as FAILED. dag_id=etl-processing, task_id=test, execution_date=20220617T103020, start_date=20220617T103026, end_date=20220617T103027
[2022-06-17 10:30:27,781] {standard_task_runner.py:97} ERROR - Failed to execute job 532 for task test (invalid input syntax for type timestamp: "NaT"
LINE 1: ... VALUES (2345692,NULL,'NaN'::float,0,'NaN'::float,'NaT'::tim...
                                                             ^
; 651)
[2022-06-17 10:30:27,879] {local_task_job.py:156} INFO - Task exited with return code 1
[2022-06-17 10:30:28,090] {local_task_job.py:273} INFO - 0 downstream tasks scheduled from follow-on schedule check
