[2022-06-17 19:30:34,067] {taskinstance.py:1159} INFO - Dependencies all met for <TaskInstance: e-t-l.transform manual__2022-06-17T19:30:29.524919+00:00 [queued]>
[2022-06-17 19:30:34,108] {taskinstance.py:1159} INFO - Dependencies all met for <TaskInstance: e-t-l.transform manual__2022-06-17T19:30:29.524919+00:00 [queued]>
[2022-06-17 19:30:34,115] {taskinstance.py:1356} INFO - 
--------------------------------------------------------------------------------
[2022-06-17 19:30:34,126] {taskinstance.py:1357} INFO - Starting attempt 1 of 1
[2022-06-17 19:30:34,131] {taskinstance.py:1358} INFO - 
--------------------------------------------------------------------------------
[2022-06-17 19:30:34,217] {taskinstance.py:1377} INFO - Executing <Task(PythonOperator): transform> on 2022-06-17 19:30:29.524919+00:00
[2022-06-17 19:30:34,227] {standard_task_runner.py:52} INFO - Started process 19384 to run task
[2022-06-17 19:30:34,239] {standard_task_runner.py:79} INFO - Running: ['***', 'tasks', 'run', 'e-t-l', 'transform', 'manual__2022-06-17T19:30:29.524919+00:00', '--job-id', '562', '--raw', '--subdir', 'DAGS_FOLDER/new-new.py', '--cfg-path', '/tmp/tmpvsq436wm', '--error-file', '/tmp/tmpj0d3ld4p']
[2022-06-17 19:30:34,241] {standard_task_runner.py:80} INFO - Job 562: Subtask transform
[2022-06-17 19:30:34,485] {task_command.py:370} INFO - Running <TaskInstance: e-t-l.transform manual__2022-06-17T19:30:29.524919+00:00 [running]> on host fe209149cfc1
[2022-06-17 19:30:34,977] {taskinstance.py:1571} INFO - Exporting the following env vars:
AIRFLOW_CTX_DAG_OWNER=***
AIRFLOW_CTX_DAG_ID=e-t-l
AIRFLOW_CTX_TASK_ID=transform
AIRFLOW_CTX_EXECUTION_DATE=2022-06-17T19:30:29.524919+00:00
AIRFLOW_CTX_TRY_NUMBER=1
AIRFLOW_CTX_DAG_RUN_ID=manual__2022-06-17T19:30:29.524919+00:00
[2022-06-17 19:30:35,073] {taskinstance.py:1889} ERROR - Task failed with exception
Traceback (most recent call last):
  File "/home/airflow/.local/lib/python3.7/site-packages/airflow/operators/python.py", line 171, in execute
    return_value = self.execute_callable()
  File "/home/airflow/.local/lib/python3.7/site-packages/airflow/operators/python.py", line 189, in execute_callable
    return self.python_callable(*self.op_args, **self.op_kwargs)
  File "/opt/airflow/dags/new-new.py", line 34, in transform_data
    source_db_store_result=extract_data["store_result"]
TypeError: 'NoneType' object is not subscriptable
[2022-06-17 19:30:35,143] {taskinstance.py:1400} INFO - Marking task as FAILED. dag_id=e-t-l, task_id=transform, execution_date=20220617T193029, start_date=20220617T193034, end_date=20220617T193035
[2022-06-17 19:30:35,230] {standard_task_runner.py:97} ERROR - Failed to execute job 562 for task transform ('NoneType' object is not subscriptable; 19384)
[2022-06-17 19:30:35,265] {local_task_job.py:156} INFO - Task exited with return code 1
[2022-06-17 19:30:35,451] {local_task_job.py:273} INFO - 0 downstream tasks scheduled from follow-on schedule check
