[2022-06-17 10:38:18,205] {taskinstance.py:1159} INFO - Dependencies all met for <TaskInstance: etl-processing.test manual__2022-06-17T10:38:13.633175+00:00 [queued]>
[2022-06-17 10:38:18,271] {taskinstance.py:1159} INFO - Dependencies all met for <TaskInstance: etl-processing.test manual__2022-06-17T10:38:13.633175+00:00 [queued]>
[2022-06-17 10:38:18,272] {taskinstance.py:1356} INFO - 
--------------------------------------------------------------------------------
[2022-06-17 10:38:18,277] {taskinstance.py:1357} INFO - Starting attempt 1 of 1
[2022-06-17 10:38:18,279] {taskinstance.py:1358} INFO - 
--------------------------------------------------------------------------------
[2022-06-17 10:38:18,443] {taskinstance.py:1377} INFO - Executing <Task(PythonOperator): test> on 2022-06-17 10:38:13.633175+00:00
[2022-06-17 10:38:18,487] {standard_task_runner.py:52} INFO - Started process 933 to run task
[2022-06-17 10:38:18,520] {standard_task_runner.py:79} INFO - Running: ['***', 'tasks', 'run', 'etl-processing', 'test', 'manual__2022-06-17T10:38:13.633175+00:00', '--job-id', '533', '--raw', '--subdir', 'DAGS_FOLDER/testing_etl.py', '--cfg-path', '/tmp/tmpdk1mj3q3', '--error-file', '/tmp/tmp0g5n7jq3']
[2022-06-17 10:38:18,532] {standard_task_runner.py:80} INFO - Job 533: Subtask test
[2022-06-17 10:38:19,101] {task_command.py:370} INFO - Running <TaskInstance: etl-processing.test manual__2022-06-17T10:38:13.633175+00:00 [running]> on host fe209149cfc1
[2022-06-17 10:38:19,825] {taskinstance.py:1571} INFO - Exporting the following env vars:
AIRFLOW_CTX_DAG_OWNER=***
AIRFLOW_CTX_DAG_ID=etl-processing
AIRFLOW_CTX_TASK_ID=test
AIRFLOW_CTX_EXECUTION_DATE=2022-06-17T10:38:13.633175+00:00
AIRFLOW_CTX_TRY_NUMBER=1
AIRFLOW_CTX_DAG_RUN_ID=manual__2022-06-17T10:38:13.633175+00:00
[2022-06-17 10:38:19,918] {base.py:68} INFO - Using connection ID 'mysql_con' for task execution.
[2022-06-17 10:38:20,117] {base.py:68} INFO - Using connection ID 'postgres_conn' for task execution.
[2022-06-17 10:38:20,341] {taskinstance.py:1889} ERROR - Task failed with exception
Traceback (most recent call last):
  File "/home/airflow/.local/lib/python3.7/site-packages/airflow/operators/python.py", line 171, in execute
    return_value = self.execute_callable()
  File "/home/airflow/.local/lib/python3.7/site-packages/airflow/operators/python.py", line 189, in execute_callable
    return self.python_callable(*self.op_args, **self.op_kwargs)
  File "/opt/airflow/dags/testing_etl.py", line 51, in get_source_data
    cursor.execute(sql, tuple(i))
psycopg2.errors.InvalidDatetimeFormat: invalid input syntax for type timestamp: "NaT"
LINE 1: ... VALUES (2345692,NULL,'NaN'::float,0,'NaN'::float,'NaT'::tim...
                                                             ^

[2022-06-17 10:38:20,377] {taskinstance.py:1400} INFO - Marking task as FAILED. dag_id=etl-processing, task_id=test, execution_date=20220617T103813, start_date=20220617T103818, end_date=20220617T103820
[2022-06-17 10:38:20,411] {standard_task_runner.py:97} ERROR - Failed to execute job 533 for task test (invalid input syntax for type timestamp: "NaT"
LINE 1: ... VALUES (2345692,NULL,'NaN'::float,0,'NaN'::float,'NaT'::tim...
                                                             ^
; 933)
[2022-06-17 10:38:20,448] {local_task_job.py:156} INFO - Task exited with return code 1
[2022-06-17 10:38:20,658] {local_task_job.py:273} INFO - 0 downstream tasks scheduled from follow-on schedule check
