[2022-06-17 08:59:04,798] {taskinstance.py:1159} INFO - Dependencies all met for <TaskInstance: postgre_insert.create_pet_table manual__2022-06-17T08:58:54.365390+00:00 [queued]>
[2022-06-17 08:59:04,931] {taskinstance.py:1159} INFO - Dependencies all met for <TaskInstance: postgre_insert.create_pet_table manual__2022-06-17T08:58:54.365390+00:00 [queued]>
[2022-06-17 08:59:04,954] {taskinstance.py:1356} INFO - 
--------------------------------------------------------------------------------
[2022-06-17 08:59:04,970] {taskinstance.py:1357} INFO - Starting attempt 1 of 1
[2022-06-17 08:59:04,986] {taskinstance.py:1358} INFO - 
--------------------------------------------------------------------------------
[2022-06-17 08:59:05,264] {taskinstance.py:1377} INFO - Executing <Task(PostgresOperator): create_pet_table> on 2022-06-17 08:58:54.365390+00:00
[2022-06-17 08:59:05,463] {standard_task_runner.py:79} INFO - Running: ['***', 'tasks', 'run', 'postgre_insert', 'create_pet_table', 'manual__2022-06-17T08:58:54.365390+00:00', '--job-id', '507', '--raw', '--subdir', 'DAGS_FOLDER/postgre_conn.py', '--cfg-path', '/tmp/tmpk41k1l93', '--error-file', '/tmp/tmpu_qdvxyj']
[2022-06-17 08:59:05,467] {standard_task_runner.py:80} INFO - Job 507: Subtask create_pet_table
[2022-06-17 08:59:05,434] {standard_task_runner.py:52} INFO - Started process 2957 to run task
[2022-06-17 08:59:06,519] {task_command.py:370} INFO - Running <TaskInstance: postgre_insert.create_pet_table manual__2022-06-17T08:58:54.365390+00:00 [running]> on host fe209149cfc1
[2022-06-17 08:59:08,561] {taskinstance.py:1571} INFO - Exporting the following env vars:
AIRFLOW_CTX_DAG_OWNER=***
AIRFLOW_CTX_DAG_ID=postgre_insert
AIRFLOW_CTX_TASK_ID=create_pet_table
AIRFLOW_CTX_EXECUTION_DATE=2022-06-17T08:58:54.365390+00:00
AIRFLOW_CTX_TRY_NUMBER=1
AIRFLOW_CTX_DAG_RUN_ID=manual__2022-06-17T08:58:54.365390+00:00
[2022-06-17 08:59:09,439] {taskinstance.py:1889} ERROR - Task failed with exception
Traceback (most recent call last):
  File "/home/airflow/.local/lib/python3.7/site-packages/airflow/providers/postgres/operators/postgres.py", line 92, in execute
    self.hook.run(self.sql, self.autocommit, parameters=self.parameters)
  File "/home/airflow/.local/lib/python3.7/site-packages/airflow/hooks/dbapi.py", line 186, in run
    with closing(self.get_conn()) as conn:
  File "/home/airflow/.local/lib/python3.7/site-packages/airflow/providers/postgres/hooks/postgres.py", line 86, in get_conn
    conn = deepcopy(self.connection or self.get_connection(conn_id))
  File "/home/airflow/.local/lib/python3.7/site-packages/airflow/hooks/base.py", line 67, in get_connection
    conn = Connection.get_connection_from_secrets(conn_id)
  File "/home/airflow/.local/lib/python3.7/site-packages/airflow/models/connection.py", line 430, in get_connection_from_secrets
    raise AirflowNotFoundException(f"The conn_id `{conn_id}` isn't defined")
airflow.exceptions.AirflowNotFoundException: The conn_id `postgres_default` isn't defined
[2022-06-17 08:59:09,663] {taskinstance.py:1400} INFO - Marking task as FAILED. dag_id=postgre_insert, task_id=create_pet_table, execution_date=20220617T085854, start_date=20220617T085904, end_date=20220617T085909
[2022-06-17 08:59:12,228] {standard_task_runner.py:97} ERROR - Failed to execute job 507 for task create_pet_table (The conn_id `postgres_default` isn't defined; 2957)
[2022-06-17 08:59:12,496] {local_task_job.py:156} INFO - Task exited with return code 1
[2022-06-17 08:59:13,038] {local_task_job.py:273} INFO - 0 downstream tasks scheduled from follow-on schedule check
