[2022-06-20 07:48:22,449] {taskinstance.py:1159} INFO - Dependencies all met for <TaskInstance: etl-processing.extract manual__2022-06-20T07:48:15.222026+00:00 [queued]>
[2022-06-20 07:48:22,532] {taskinstance.py:1159} INFO - Dependencies all met for <TaskInstance: etl-processing.extract manual__2022-06-20T07:48:15.222026+00:00 [queued]>
[2022-06-20 07:48:22,533] {taskinstance.py:1356} INFO - 
--------------------------------------------------------------------------------
[2022-06-20 07:48:22,533] {taskinstance.py:1357} INFO - Starting attempt 1 of 1
[2022-06-20 07:48:22,545] {taskinstance.py:1358} INFO - 
--------------------------------------------------------------------------------
[2022-06-20 07:48:22,721] {taskinstance.py:1377} INFO - Executing <Task(PythonOperator): extract> on 2022-06-20 07:48:15.222026+00:00
[2022-06-20 07:48:22,831] {standard_task_runner.py:52} INFO - Started process 5322 to run task
[2022-06-20 07:48:22,875] {standard_task_runner.py:79} INFO - Running: ['***', 'tasks', 'run', 'etl-processing', 'extract', 'manual__2022-06-20T07:48:15.222026+00:00', '--job-id', '631', '--raw', '--subdir', 'DAGS_FOLDER/etl_processing.py', '--cfg-path', '/tmp/tmpnrw1gd9f', '--error-file', '/tmp/tmptd0lnp87']
[2022-06-20 07:48:22,915] {standard_task_runner.py:80} INFO - Job 631: Subtask extract
[2022-06-20 07:48:23,737] {task_command.py:370} INFO - Running <TaskInstance: etl-processing.extract manual__2022-06-20T07:48:15.222026+00:00 [running]> on host fe209149cfc1
[2022-06-20 07:48:24,731] {taskinstance.py:1571} INFO - Exporting the following env vars:
AIRFLOW_CTX_DAG_OWNER=***
AIRFLOW_CTX_DAG_ID=etl-processing
AIRFLOW_CTX_TASK_ID=extract
AIRFLOW_CTX_EXECUTION_DATE=2022-06-20T07:48:15.222026+00:00
AIRFLOW_CTX_TRY_NUMBER=1
AIRFLOW_CTX_DAG_RUN_ID=manual__2022-06-20T07:48:15.222026+00:00
[2022-06-20 07:48:24,802] {base.py:68} INFO - Using connection ID 'mysql_con' for task execution.
[2022-06-20 07:48:24,825] {taskinstance.py:1889} ERROR - Task failed with exception
Traceback (most recent call last):
  File "/home/airflow/.local/lib/python3.7/site-packages/airflow/operators/python.py", line 171, in execute
    return_value = self.execute_callable()
  File "/home/airflow/.local/lib/python3.7/site-packages/airflow/operators/python.py", line 189, in execute_callable
    return self.python_callable(*self.op_args, **self.op_kwargs)
  File "/opt/airflow/dags/etl_processing.py", line 23, in get_source_data
    source_db_store_result = source_db_connection.get_pandas_df(extraction_sql['store_sql'])
  File "/home/airflow/.local/lib/python3.7/site-packages/airflow/hooks/dbapi.py", line 128, in get_pandas_df
    with closing(self.get_conn()) as conn:
  File "/home/airflow/.local/lib/python3.7/site-packages/airflow/providers/mysql/hooks/mysql.py", line 166, in get_conn
    return MySQLdb.connect(**conn_config)
  File "/home/airflow/.local/lib/python3.7/site-packages/MySQLdb/__init__.py", line 123, in Connect
    return Connection(*args, **kwargs)
  File "/home/airflow/.local/lib/python3.7/site-packages/MySQLdb/connections.py", line 185, in __init__
    super().__init__(*args, **kwargs2)
MySQLdb._exceptions.OperationalError: (2003, "Can't connect to MySQL server on '172.21.0.2:3306' (111)")
[2022-06-20 07:48:24,989] {taskinstance.py:1400} INFO - Marking task as FAILED. dag_id=etl-processing, task_id=extract, execution_date=20220620T074815, start_date=20220620T074822, end_date=20220620T074824
[2022-06-20 07:48:25,261] {standard_task_runner.py:97} ERROR - Failed to execute job 631 for task extract ((2003, "Can't connect to MySQL server on '172.21.0.2:3306' (111)"); 5322)
[2022-06-20 07:48:25,333] {local_task_job.py:156} INFO - Task exited with return code 1
[2022-06-20 07:48:25,944] {local_task_job.py:273} INFO - 0 downstream tasks scheduled from follow-on schedule check
