[2022-06-20 07:20:04,696] {taskinstance.py:1159} INFO - Dependencies all met for <TaskInstance: etl-processing.extract scheduled__2022-06-20T07:00:00+00:00 [queued]>
[2022-06-20 07:20:04,729] {taskinstance.py:1159} INFO - Dependencies all met for <TaskInstance: etl-processing.extract scheduled__2022-06-20T07:00:00+00:00 [queued]>
[2022-06-20 07:20:04,735] {taskinstance.py:1356} INFO - 
--------------------------------------------------------------------------------
[2022-06-20 07:20:04,759] {taskinstance.py:1357} INFO - Starting attempt 1 of 1
[2022-06-20 07:20:04,762] {taskinstance.py:1358} INFO - 
--------------------------------------------------------------------------------
[2022-06-20 07:20:04,799] {taskinstance.py:1377} INFO - Executing <Task(PythonOperator): extract> on 2022-06-20 07:00:00+00:00
[2022-06-20 07:20:04,806] {standard_task_runner.py:52} INFO - Started process 4199 to run task
[2022-06-20 07:20:04,811] {standard_task_runner.py:79} INFO - Running: ['***', 'tasks', 'run', 'etl-processing', 'extract', 'scheduled__2022-06-20T07:00:00+00:00', '--job-id', '628', '--raw', '--subdir', 'DAGS_FOLDER/etl_processing.py', '--cfg-path', '/tmp/tmp196rubgr', '--error-file', '/tmp/tmpb_4xrfsd']
[2022-06-20 07:20:04,812] {standard_task_runner.py:80} INFO - Job 628: Subtask extract
[2022-06-20 07:20:04,952] {task_command.py:370} INFO - Running <TaskInstance: etl-processing.extract scheduled__2022-06-20T07:00:00+00:00 [running]> on host fe209149cfc1
[2022-06-20 07:20:05,180] {taskinstance.py:1571} INFO - Exporting the following env vars:
AIRFLOW_CTX_DAG_OWNER=***
AIRFLOW_CTX_DAG_ID=etl-processing
AIRFLOW_CTX_TASK_ID=extract
AIRFLOW_CTX_EXECUTION_DATE=2022-06-20T07:00:00+00:00
AIRFLOW_CTX_TRY_NUMBER=1
AIRFLOW_CTX_DAG_RUN_ID=scheduled__2022-06-20T07:00:00+00:00
[2022-06-20 07:20:05,212] {base.py:68} INFO - Using connection ID 'mysql_con' for task execution.
[2022-06-20 07:20:05,223] {taskinstance.py:1889} ERROR - Task failed with exception
Traceback (most recent call last):
  File "/home/airflow/.local/lib/python3.7/site-packages/airflow/operators/python.py", line 171, in execute
    return_value = self.execute_callable()
  File "/home/airflow/.local/lib/python3.7/site-packages/airflow/operators/python.py", line 189, in execute_callable
    return self.python_callable(*self.op_args, **self.op_kwargs)
  File "/opt/airflow/dags/etl_processing.py", line 23, in get_source_data
    source_db_store_result = source_db_connection.get_pandas_df(extraction_sql['store_sql'])
  File "/home/airflow/.local/lib/python3.7/site-packages/airflow/hooks/dbapi.py", line 128, in get_pandas_df
    with closing(self.get_conn()) as conn:
  File "/home/airflow/.local/lib/python3.7/site-packages/airflow/providers/mysql/hooks/mysql.py", line 166, in get_conn
    return MySQLdb.connect(**conn_config)
  File "/home/airflow/.local/lib/python3.7/site-packages/MySQLdb/__init__.py", line 123, in Connect
    return Connection(*args, **kwargs)
  File "/home/airflow/.local/lib/python3.7/site-packages/MySQLdb/connections.py", line 185, in __init__
    super().__init__(*args, **kwargs2)
MySQLdb._exceptions.OperationalError: (2003, "Can't connect to MySQL server on '172.21.0.2:3306' (111)")
[2022-06-20 07:20:05,243] {taskinstance.py:1400} INFO - Marking task as FAILED. dag_id=etl-processing, task_id=extract, execution_date=20220620T070000, start_date=20220620T072004, end_date=20220620T072005
[2022-06-20 07:20:05,269] {standard_task_runner.py:97} ERROR - Failed to execute job 628 for task extract ((2003, "Can't connect to MySQL server on '172.21.0.2:3306' (111)"); 4199)
[2022-06-20 07:20:05,308] {local_task_job.py:156} INFO - Task exited with return code 1
[2022-06-20 07:20:05,416] {local_task_job.py:273} INFO - 0 downstream tasks scheduled from follow-on schedule check
