[2022-06-17 18:25:25,285] {taskinstance.py:1159} INFO - Dependencies all met for <TaskInstance: e-t-l.test manual__2022-06-17T18:25:11.579595+00:00 [queued]>
[2022-06-17 18:25:25,427] {taskinstance.py:1159} INFO - Dependencies all met for <TaskInstance: e-t-l.test manual__2022-06-17T18:25:11.579595+00:00 [queued]>
[2022-06-17 18:25:25,428] {taskinstance.py:1356} INFO - 
--------------------------------------------------------------------------------
[2022-06-17 18:25:25,439] {taskinstance.py:1357} INFO - Starting attempt 1 of 1
[2022-06-17 18:25:25,455] {taskinstance.py:1358} INFO - 
--------------------------------------------------------------------------------
[2022-06-17 18:25:25,648] {taskinstance.py:1377} INFO - Executing <Task(PythonOperator): test> on 2022-06-17 18:25:11.579595+00:00
[2022-06-17 18:25:25,715] {standard_task_runner.py:52} INFO - Started process 17482 to run task
[2022-06-17 18:25:25,756] {standard_task_runner.py:79} INFO - Running: ['***', 'tasks', 'run', 'e-t-l', 'test', 'manual__2022-06-17T18:25:11.579595+00:00', '--job-id', '541', '--raw', '--subdir', 'DAGS_FOLDER/new-new.py', '--cfg-path', '/tmp/tmp01o34_vw', '--error-file', '/tmp/tmp77qdpwg3']
[2022-06-17 18:25:25,775] {standard_task_runner.py:80} INFO - Job 541: Subtask test
[2022-06-17 18:25:26,573] {task_command.py:370} INFO - Running <TaskInstance: e-t-l.test manual__2022-06-17T18:25:11.579595+00:00 [running]> on host fe209149cfc1
[2022-06-17 18:25:27,864] {taskinstance.py:1571} INFO - Exporting the following env vars:
AIRFLOW_CTX_DAG_OWNER=***
AIRFLOW_CTX_DAG_ID=e-t-l
AIRFLOW_CTX_TASK_ID=test
AIRFLOW_CTX_EXECUTION_DATE=2022-06-17T18:25:11.579595+00:00
AIRFLOW_CTX_TRY_NUMBER=1
AIRFLOW_CTX_DAG_RUN_ID=manual__2022-06-17T18:25:11.579595+00:00
[2022-06-17 18:25:28,026] {taskinstance.py:1889} ERROR - Task failed with exception
Traceback (most recent call last):
  File "/home/airflow/.local/lib/python3.7/site-packages/airflow/operators/python.py", line 171, in execute
    return_value = self.execute_callable()
  File "/home/airflow/.local/lib/python3.7/site-packages/airflow/operators/python.py", line 189, in execute_callable
    return self.python_callable(*self.op_args, **self.op_kwargs)
  File "/opt/airflow/dags/new-new.py", line 20, in get_source_data
    extraction_sql=Variable.get("extraction_sql",deserialize_json=True)
  File "/home/airflow/.local/lib/python3.7/site-packages/airflow/models/variable.py", line 141, in get
    obj = json.loads(var_val)
  File "/usr/local/lib/python3.7/json/__init__.py", line 348, in loads
    return _default_decoder.decode(s)
  File "/usr/local/lib/python3.7/json/decoder.py", line 337, in decode
    obj, end = self.raw_decode(s, idx=_w(s, 0).end())
  File "/usr/local/lib/python3.7/json/decoder.py", line 353, in raw_decode
    obj, end = self.scan_once(s, idx)
json.decoder.JSONDecodeError: Expecting ',' delimiter: line 1 column 17 (char 16)
[2022-06-17 18:25:28,327] {taskinstance.py:1400} INFO - Marking task as FAILED. dag_id=e-t-l, task_id=test, execution_date=20220617T182511, start_date=20220617T182525, end_date=20220617T182528
[2022-06-17 18:25:28,537] {standard_task_runner.py:97} ERROR - Failed to execute job 541 for task test (Expecting ',' delimiter: line 1 column 17 (char 16); 17482)
[2022-06-17 18:25:28,655] {local_task_job.py:156} INFO - Task exited with return code 1
[2022-06-17 18:25:29,015] {local_task_job.py:273} INFO - 0 downstream tasks scheduled from follow-on schedule check
