[2022-06-17 10:19:35,040] {taskinstance.py:1159} INFO - Dependencies all met for <TaskInstance: etl-processing.test manual__2022-06-17T10:19:29.330083+00:00 [queued]>
[2022-06-17 10:19:35,091] {taskinstance.py:1159} INFO - Dependencies all met for <TaskInstance: etl-processing.test manual__2022-06-17T10:19:29.330083+00:00 [queued]>
[2022-06-17 10:19:35,092] {taskinstance.py:1356} INFO - 
--------------------------------------------------------------------------------
[2022-06-17 10:19:35,092] {taskinstance.py:1357} INFO - Starting attempt 1 of 1
[2022-06-17 10:19:35,093] {taskinstance.py:1358} INFO - 
--------------------------------------------------------------------------------
[2022-06-17 10:19:35,188] {taskinstance.py:1377} INFO - Executing <Task(PythonOperator): test> on 2022-06-17 10:19:29.330083+00:00
[2022-06-17 10:19:35,222] {standard_task_runner.py:79} INFO - Running: ['***', 'tasks', 'run', 'etl-processing', 'test', 'manual__2022-06-17T10:19:29.330083+00:00', '--job-id', '529', '--raw', '--subdir', 'DAGS_FOLDER/testing_etl.py', '--cfg-path', '/tmp/tmp5uhluk32', '--error-file', '/tmp/tmpi0o69yju']
[2022-06-17 10:19:35,210] {standard_task_runner.py:52} INFO - Started process 283 to run task
[2022-06-17 10:19:35,225] {standard_task_runner.py:80} INFO - Job 529: Subtask test
[2022-06-17 10:19:35,453] {task_command.py:370} INFO - Running <TaskInstance: etl-processing.test manual__2022-06-17T10:19:29.330083+00:00 [running]> on host fe209149cfc1
[2022-06-17 10:19:35,784] {taskinstance.py:1571} INFO - Exporting the following env vars:
AIRFLOW_CTX_DAG_OWNER=***
AIRFLOW_CTX_DAG_ID=etl-processing
AIRFLOW_CTX_TASK_ID=test
AIRFLOW_CTX_EXECUTION_DATE=2022-06-17T10:19:29.330083+00:00
AIRFLOW_CTX_TRY_NUMBER=1
AIRFLOW_CTX_DAG_RUN_ID=manual__2022-06-17T10:19:29.330083+00:00
[2022-06-17 10:19:38,642] {base.py:68} INFO - Using connection ID 'mysql_con' for task execution.
[2022-06-17 10:19:42,754] {base.py:68} INFO - Using connection ID 'postgres_conn' for task execution.
[2022-06-17 10:19:42,767] {taskinstance.py:1889} ERROR - Task failed with exception
Traceback (most recent call last):
  File "/home/airflow/.local/lib/python3.7/site-packages/airflow/operators/python.py", line 171, in execute
    return_value = self.execute_callable()
  File "/home/airflow/.local/lib/python3.7/site-packages/airflow/operators/python.py", line 189, in execute_callable
    return self.python_callable(*self.op_args, **self.op_kwargs)
  File "/opt/airflow/dags/testing_etl.py", line 37, in get_source_data
    db_connection=psycopg2.connect(engine)
  File "/home/airflow/.local/lib/python3.7/site-packages/psycopg2/__init__.py", line 121, in connect
    dsn = _ext.make_dsn(dsn, **kwargs)
  File "/home/airflow/.local/lib/python3.7/site-packages/psycopg2/extensions.py", line 145, in make_dsn
    parse_dsn(dsn)
TypeError: Expected bytes or unicode string, got Engine instead
[2022-06-17 10:19:42,953] {taskinstance.py:1400} INFO - Marking task as FAILED. dag_id=etl-processing, task_id=test, execution_date=20220617T101929, start_date=20220617T101935, end_date=20220617T101942
[2022-06-17 10:19:43,314] {standard_task_runner.py:97} ERROR - Failed to execute job 529 for task test (Expected bytes or unicode string, got Engine instead; 283)
[2022-06-17 10:19:43,455] {local_task_job.py:156} INFO - Task exited with return code 1
[2022-06-17 10:19:43,886] {local_task_job.py:273} INFO - 0 downstream tasks scheduled from follow-on schedule check
