[2022-06-20 21:40:51,762] {taskinstance.py:1159} INFO - Dependencies all met for <TaskInstance: etl-processing.health_check scheduled__2022-06-20T21:20:00+00:00 [queued]>
[2022-06-20 21:40:51,871] {taskinstance.py:1159} INFO - Dependencies all met for <TaskInstance: etl-processing.health_check scheduled__2022-06-20T21:20:00+00:00 [queued]>
[2022-06-20 21:40:51,876] {taskinstance.py:1356} INFO - 
--------------------------------------------------------------------------------
[2022-06-20 21:40:51,878] {taskinstance.py:1357} INFO - Starting attempt 1 of 1
[2022-06-20 21:40:51,879] {taskinstance.py:1358} INFO - 
--------------------------------------------------------------------------------
[2022-06-20 21:40:52,052] {taskinstance.py:1377} INFO - Executing <Task(BashOperator): health_check> on 2022-06-20 21:20:00+00:00
[2022-06-20 21:40:52,114] {standard_task_runner.py:79} INFO - Running: ['***', 'tasks', 'run', 'etl-processing', 'health_check', 'scheduled__2022-06-20T21:20:00+00:00', '--job-id', '734', '--raw', '--subdir', 'DAGS_FOLDER/etl_processing.py', '--cfg-path', '/tmp/tmptccyoow7', '--error-file', '/tmp/tmpk06husy9']
[2022-06-20 21:40:52,127] {standard_task_runner.py:80} INFO - Job 734: Subtask health_check
[2022-06-20 21:40:52,125] {standard_task_runner.py:52} INFO - Started process 6017 to run task
[2022-06-20 21:40:52,840] {task_command.py:370} INFO - Running <TaskInstance: etl-processing.health_check scheduled__2022-06-20T21:20:00+00:00 [running]> on host fe209149cfc1
[2022-06-20 21:40:53,302] {taskinstance.py:1889} ERROR - Task failed with exception
Traceback (most recent call last):
  File "/home/airflow/.local/lib/python3.7/site-packages/airflow/models/taskinstance.py", line 1451, in _run_raw_task
    self._execute_task_with_callbacks(context, test_mode)
  File "/home/airflow/.local/lib/python3.7/site-packages/airflow/models/taskinstance.py", line 1555, in _execute_task_with_callbacks
    task_orig = self.render_templates(context=context)
  File "/home/airflow/.local/lib/python3.7/site-packages/airflow/models/taskinstance.py", line 2212, in render_templates
    rendered_task = self.task.render_template_fields(context)
  File "/home/airflow/.local/lib/python3.7/site-packages/airflow/models/baseoperator.py", line 1185, in render_template_fields
    self._do_render_template_fields(self, self.template_fields, context, jinja_env, set())
  File "/home/airflow/.local/lib/python3.7/site-packages/airflow/utils/session.py", line 71, in wrapper
    return func(*args, session=session, **kwargs)
  File "/home/airflow/.local/lib/python3.7/site-packages/airflow/models/abstractoperator.py", line 348, in _do_render_template_fields
    seen_oids,
  File "/home/airflow/.local/lib/python3.7/site-packages/airflow/models/abstractoperator.py", line 385, in render_template
    template = jinja_env.get_template(value)
  File "/home/airflow/.local/lib/python3.7/site-packages/jinja2/environment.py", line 997, in get_template
    return self._load_template(name, globals)
  File "/home/airflow/.local/lib/python3.7/site-packages/jinja2/environment.py", line 958, in _load_template
    template = self.loader.load(self, name, self.make_globals(globals))
  File "/home/airflow/.local/lib/python3.7/site-packages/jinja2/loaders.py", line 125, in load
    source, filename, uptodate = self.get_source(environment, name)
  File "/home/airflow/.local/lib/python3.7/site-packages/jinja2/loaders.py", line 214, in get_source
    raise TemplateNotFound(template)
jinja2.exceptions.TemplateNotFound: \health_check.sh
[2022-06-20 21:40:53,408] {taskinstance.py:1400} INFO - Marking task as FAILED. dag_id=etl-processing, task_id=health_check, execution_date=20220620T212000, start_date=20220620T214051, end_date=20220620T214053
[2022-06-20 21:40:53,529] {standard_task_runner.py:97} ERROR - Failed to execute job 734 for task health_check (\health_check.sh; 6017)
[2022-06-20 21:40:53,603] {local_task_job.py:156} INFO - Task exited with return code 1
[2022-06-20 21:40:53,897] {local_task_job.py:273} INFO - 0 downstream tasks scheduled from follow-on schedule check
