[2022-06-17 19:14:57,875] {taskinstance.py:1159} INFO - Dependencies all met for <TaskInstance: e-t-l.test manual__2022-06-17T19:14:48.275893+00:00 [queued]>
[2022-06-17 19:14:57,976] {taskinstance.py:1159} INFO - Dependencies all met for <TaskInstance: e-t-l.test manual__2022-06-17T19:14:48.275893+00:00 [queued]>
[2022-06-17 19:14:57,991] {taskinstance.py:1356} INFO - 
--------------------------------------------------------------------------------
[2022-06-17 19:14:58,004] {taskinstance.py:1357} INFO - Starting attempt 1 of 1
[2022-06-17 19:14:58,012] {taskinstance.py:1358} INFO - 
--------------------------------------------------------------------------------
[2022-06-17 19:14:58,209] {taskinstance.py:1377} INFO - Executing <Task(PythonOperator): test> on 2022-06-17 19:14:48.275893+00:00
[2022-06-17 19:14:58,259] {standard_task_runner.py:52} INFO - Started process 18925 to run task
[2022-06-17 19:14:58,290] {standard_task_runner.py:79} INFO - Running: ['***', 'tasks', 'run', 'e-t-l', 'test', 'manual__2022-06-17T19:14:48.275893+00:00', '--job-id', '557', '--raw', '--subdir', 'DAGS_FOLDER/new-new.py', '--cfg-path', '/tmp/tmpzslwskcy', '--error-file', '/tmp/tmpoyu5i1fg']
[2022-06-17 19:14:58,330] {standard_task_runner.py:80} INFO - Job 557: Subtask test
[2022-06-17 19:14:58,997] {task_command.py:370} INFO - Running <TaskInstance: e-t-l.test manual__2022-06-17T19:14:48.275893+00:00 [running]> on host fe209149cfc1
[2022-06-17 19:14:59,858] {taskinstance.py:1571} INFO - Exporting the following env vars:
AIRFLOW_CTX_DAG_OWNER=***
AIRFLOW_CTX_DAG_ID=e-t-l
AIRFLOW_CTX_TASK_ID=test
AIRFLOW_CTX_EXECUTION_DATE=2022-06-17T19:14:48.275893+00:00
AIRFLOW_CTX_TRY_NUMBER=1
AIRFLOW_CTX_DAG_RUN_ID=manual__2022-06-17T19:14:48.275893+00:00
[2022-06-17 19:14:59,900] {taskinstance.py:1889} ERROR - Task failed with exception
Traceback (most recent call last):
  File "/home/airflow/.local/lib/python3.7/site-packages/airflow/operators/python.py", line 171, in execute
    return_value = self.execute_callable()
  File "/home/airflow/.local/lib/python3.7/site-packages/airflow/operators/python.py", line 189, in execute_callable
    return self.python_callable(*self.op_args, **self.op_kwargs)
  File "/opt/airflow/dags/new-new.py", line 22, in get_source_data
    extraction_sql=Variable.get("extraction_sql",deserialize_json=True)
  File "/home/airflow/.local/lib/python3.7/site-packages/airflow/models/variable.py", line 141, in get
    obj = json.loads(var_val)
  File "/usr/local/lib/python3.7/json/__init__.py", line 348, in loads
    return _default_decoder.decode(s)
  File "/usr/local/lib/python3.7/json/decoder.py", line 337, in decode
    obj, end = self.raw_decode(s, idx=_w(s, 0).end())
  File "/usr/local/lib/python3.7/json/decoder.py", line 353, in raw_decode
    obj, end = self.scan_once(s, idx)
json.decoder.JSONDecodeError: Invalid control character at: line 1 column 127 (char 126)
[2022-06-17 19:14:59,980] {taskinstance.py:1400} INFO - Marking task as FAILED. dag_id=e-t-l, task_id=test, execution_date=20220617T191448, start_date=20220617T191457, end_date=20220617T191459
[2022-06-17 19:15:00,073] {standard_task_runner.py:97} ERROR - Failed to execute job 557 for task test (Invalid control character at: line 1 column 127 (char 126); 18925)
[2022-06-17 19:15:00,163] {local_task_job.py:156} INFO - Task exited with return code 1
[2022-06-17 19:15:00,508] {local_task_job.py:273} INFO - 0 downstream tasks scheduled from follow-on schedule check
