[2022-06-17 19:12:40,547] {taskinstance.py:1159} INFO - Dependencies all met for <TaskInstance: e-t-l.test manual__2022-06-17T19:12:25.884089+00:00 [queued]>
[2022-06-17 19:12:40,633] {taskinstance.py:1159} INFO - Dependencies all met for <TaskInstance: e-t-l.test manual__2022-06-17T19:12:25.884089+00:00 [queued]>
[2022-06-17 19:12:40,639] {taskinstance.py:1356} INFO - 
--------------------------------------------------------------------------------
[2022-06-17 19:12:40,641] {taskinstance.py:1357} INFO - Starting attempt 1 of 1
[2022-06-17 19:12:40,655] {taskinstance.py:1358} INFO - 
--------------------------------------------------------------------------------
[2022-06-17 19:12:41,119] {taskinstance.py:1377} INFO - Executing <Task(PythonOperator): test> on 2022-06-17 19:12:25.884089+00:00
[2022-06-17 19:12:41,189] {standard_task_runner.py:52} INFO - Started process 18856 to run task
[2022-06-17 19:12:41,223] {standard_task_runner.py:79} INFO - Running: ['***', 'tasks', 'run', 'e-t-l', 'test', 'manual__2022-06-17T19:12:25.884089+00:00', '--job-id', '556', '--raw', '--subdir', 'DAGS_FOLDER/new-new.py', '--cfg-path', '/tmp/tmp4u42lna5', '--error-file', '/tmp/tmp84mx_2lj']
[2022-06-17 19:12:41,272] {standard_task_runner.py:80} INFO - Job 556: Subtask test
[2022-06-17 19:12:42,773] {task_command.py:370} INFO - Running <TaskInstance: e-t-l.test manual__2022-06-17T19:12:25.884089+00:00 [running]> on host fe209149cfc1
[2022-06-17 19:12:46,051] {taskinstance.py:1571} INFO - Exporting the following env vars:
AIRFLOW_CTX_DAG_OWNER=***
AIRFLOW_CTX_DAG_ID=e-t-l
AIRFLOW_CTX_TASK_ID=test
AIRFLOW_CTX_EXECUTION_DATE=2022-06-17T19:12:25.884089+00:00
AIRFLOW_CTX_TRY_NUMBER=1
AIRFLOW_CTX_DAG_RUN_ID=manual__2022-06-17T19:12:25.884089+00:00
[2022-06-17 19:12:46,123] {taskinstance.py:1889} ERROR - Task failed with exception
Traceback (most recent call last):
  File "/home/airflow/.local/lib/python3.7/site-packages/airflow/operators/python.py", line 171, in execute
    return_value = self.execute_callable()
  File "/home/airflow/.local/lib/python3.7/site-packages/airflow/operators/python.py", line 189, in execute_callable
    return self.python_callable(*self.op_args, **self.op_kwargs)
  File "/opt/airflow/dags/new-new.py", line 22, in get_source_data
    extraction_sql=Variable.get("extraction_sql",deserialize_json=True)
  File "/home/airflow/.local/lib/python3.7/site-packages/airflow/models/variable.py", line 141, in get
    obj = json.loads(var_val)
  File "/usr/local/lib/python3.7/json/__init__.py", line 348, in loads
    return _default_decoder.decode(s)
  File "/usr/local/lib/python3.7/json/decoder.py", line 337, in decode
    obj, end = self.raw_decode(s, idx=_w(s, 0).end())
  File "/usr/local/lib/python3.7/json/decoder.py", line 353, in raw_decode
    obj, end = self.scan_once(s, idx)
json.decoder.JSONDecodeError: Invalid control character at: line 1 column 23 (char 22)
[2022-06-17 19:12:46,588] {taskinstance.py:1400} INFO - Marking task as FAILED. dag_id=e-t-l, task_id=test, execution_date=20220617T191225, start_date=20220617T191240, end_date=20220617T191246
[2022-06-17 19:12:47,110] {standard_task_runner.py:97} ERROR - Failed to execute job 556 for task test (Invalid control character at: line 1 column 23 (char 22); 18856)
[2022-06-17 19:12:47,162] {local_task_job.py:156} INFO - Task exited with return code 1
[2022-06-17 19:12:47,481] {local_task_job.py:273} INFO - 0 downstream tasks scheduled from follow-on schedule check
